import { ContinueSentinel, hasOwn } from './utils'
import values from './values'

function pushTryEntry(locs) {
  var entry = { tryLoc: locs[0] };

  if (1 in locs) {
    entry.catchLoc = locs[1];
  }

  if (2 in locs) {
    entry.finallyLoc = locs[2];
    entry.afterLoc = locs[3];
  }

  this.tryEntries.push(entry);
}

function resetTryEntry(entry) {
  var record = entry.completion || {};
  record.type = "normal";
  delete record.arg;
  entry.completion = record;
}

export default class Context {
  constructor(tryLocsList) {
    // The root entry object (effectively a try statement without a catch
    // or a finally block) gives us a place to store values thrown from
    // locations where there is no enclosing try statement.
    this.tryEntries = [{ tryLoc: "root" }];
    tryLocsList.forEach(pushTryEntry, this);
    this.reset(true);
  }

  reset(skipTempReset) {
    this.prev = 0;
    this.next = 0;
    // Resetting context._sent for legacy support of Babel's
    // function.sent implementation.
    this.sent = this._sent = undefined;
    this.done = false;
    this.delegate = null;

    this.method = "next";
    this.arg = undefined;

    this.tryEntries.forEach(resetTryEntry);

    if (!skipTempReset) {
      for (var name in this) {
        // Not sure about the optimal order of these conditions:
        if (name.charAt(0) === "t" &&
            hasOwn.call(this, name) &&
            !isNaN(+name.slice(1))) {
          this[name] = undefined;
        }
      }
    }
  }

  stop() {
    this.done = true;

    var rootEntry = this.tryEntries[0];
    var rootRecord = rootEntry.completion;
    if (rootRecord.type === "throw") {
      throw rootRecord.arg;
    }

    return this.rval;
  }

  dispatchException(exception) {
    if (this.done) {
      throw exception;
    }

    var context = this;
    function handle(loc, caught) {
      record.type = "throw";
      record.arg = exception;
      context.next = loc;

      if (caught) {
        // If the dispatched exception was caught by a catch block,
        // then let that catch block handle the exception normally.
        context.method = "next";
        context.arg = undefined;
      }

      return !!caught;
    }

    for (var i = this.tryEntries.length - 1; i >= 0; --i) {
      var entry = this.tryEntries[i];
      var record = entry.completion;

      if (entry.tryLoc === "root") {
        // Exception thrown outside of any try block that could handle
        // it, so set the completion value of the entire function to
        // throw the exception.
        return handle("end");
      }

      if (entry.tryLoc <= this.prev) {
        var hasCatch = hasOwn.call(entry, "catchLoc");
        var hasFinally = hasOwn.call(entry, "finallyLoc");

        if (hasCatch && hasFinally) {
          if (this.prev < entry.catchLoc) {
            return handle(entry.catchLoc, true);
          } else if (this.prev < entry.finallyLoc) {
            return handle(entry.finallyLoc);
          }

        } else if (hasCatch) {
          if (this.prev < entry.catchLoc) {
            return handle(entry.catchLoc, true);
          }

        } else if (hasFinally) {
          if (this.prev < entry.finallyLoc) {
            return handle(entry.finallyLoc);
          }
        } else {
          throw new Error("try statement without catch or finally");
        }
      }
    }
  }

  abrupt(type, arg) {
    for (var i = this.tryEntries.length - 1; i >= 0; --i) {
      var entry = this.tryEntries[i];
      if (entry.tryLoc <= this.prev &&
          hasOwn.call(entry, "finallyLoc") &&
          this.prev < entry.finallyLoc) {
        var finallyEntry = entry;
        break;
      }
    }

    if (finallyEntry &&
        (type === "break" ||
         type === "continue") &&
        finallyEntry.tryLoc <= arg &&
        arg <= finallyEntry.finallyLoc) {
      // Ignore the finally entry if control is not jumping to a
      // location outside the try/catch block.
      finallyEntry = null;
    }

    var record = finallyEntry ? finallyEntry.completion : {};
    record.type = type;
    record.arg = arg;

    if (finallyEntry) {
      this.method = "next";
      this.next = finallyEntry.finallyLoc;
      return ContinueSentinel;
    }

    return this.complete(record);
  }

  complete(record, afterLoc) {
    if (record.type === "throw") {
      throw record.arg;
    }

    if (record.type === "break" ||
        record.type === "continue") {
      this.next = record.arg;
    } else if (record.type === "return") {
      this.rval = this.arg = record.arg;
      this.method = "return";
      this.next = "end";
    } else if (record.type === "normal" && afterLoc) {
      this.next = afterLoc;
    }

    return ContinueSentinel;
  }

  finish(finallyLoc) {
    for (var i = this.tryEntries.length - 1; i >= 0; --i) {
      var entry = this.tryEntries[i];
      if (entry.finallyLoc === finallyLoc) {
        this.complete(entry.completion, entry.afterLoc);
        resetTryEntry(entry);
        return ContinueSentinel;
      }
    }
  }

  catch(tryLoc) {
    for (var i = this.tryEntries.length - 1; i >= 0; --i) {
      var entry = this.tryEntries[i];
      if (entry.tryLoc === tryLoc) {
        var record = entry.completion;
        if (record.type === "throw") {
          var thrown = record.arg;
          resetTryEntry(entry);
        }
        return thrown;
      }
    }

    // The context.catch method must only be called with a location
    // argument that corresponds to a known catch block.
    throw new Error("illegal catch attempt");
  }

  delegateYield(iterable, resultName, nextLoc) {
    this.delegate = {
      iterator: values(iterable),
      resultName: resultName,
      nextLoc: nextLoc
    };

    if (this.method === "next") {
      // Deliberately forget the last sent value so that we don't
      // accidentally pass it on to the delegate.
      this.arg = undefined;
    }

    return ContinueSentinel;
  }
}
